
[2024-12-13 11:22:53,215] ERROR: Exception on /my_page [GET]
Traceback (most recent call last):
  File "c:\Users\kshotsu1.IXAS\AppData\Local\Programs\Python\Python310\lib\site-packages\flask\app.py", line 1473, in wsgi_app
    response = self.full_dispatch_request()
  File "c:\Users\kshotsu1.IXAS\AppData\Local\Programs\Python\Python310\lib\site-packages\flask\app.py", line 882, in full_dispatch_request
    rv = self.handle_user_exception(e)
  File "c:\Users\kshotsu1.IXAS\AppData\Local\Programs\Python\Python310\lib\site-packages\flask\app.py", line 880, in full_dispatch_request
    rv = self.dispatch_request()
  File "c:\Users\kshotsu1.IXAS\AppData\Local\Programs\Python\Python310\lib\site-packages\flask\app.py", line 865, in dispatch_request
    return self.ensure_sync(self.view_functions[rule.endpoint])(**view_args)  # type: ignore[no-any-return]
  File "C:\thread-site\vulnerability_codes\src\app.py", line 162, in my_page
    my_threads = db.execute(sql).fetchall()
sqlite3.OperationalError: no such column: ota7

[2024-12-13 11:23:08,911] ERROR: Exception on /my_page [GET]
Traceback (most recent call last):
  File "c:\Users\kshotsu1.IXAS\AppData\Local\Programs\Python\Python310\lib\site-packages\flask\app.py", line 1473, in wsgi_app
    response = self.full_dispatch_request()
  File "c:\Users\kshotsu1.IXAS\AppData\Local\Programs\Python\Python310\lib\site-packages\flask\app.py", line 882, in full_dispatch_request
    rv = self.handle_user_exception(e)
  File "c:\Users\kshotsu1.IXAS\AppData\Local\Programs\Python\Python310\lib\site-packages\flask\app.py", line 880, in full_dispatch_request
    rv = self.dispatch_request()
  File "c:\Users\kshotsu1.IXAS\AppData\Local\Programs\Python\Python310\lib\site-packages\flask\app.py", line 865, in dispatch_request
    return self.ensure_sync(self.view_functions[rule.endpoint])(**view_args)  # type: ignore[no-any-return]
  File "C:\thread-site\vulnerability_codes\src\app.py", line 162, in my_page
    my_threads = db.execute(sql).fetchall()
sqlite3.OperationalError: no such column: ota7

[2024-12-13 11:23:11,763] ERROR: Exception on /my_page [GET]
Traceback (most recent call last):
  File "c:\Users\kshotsu1.IXAS\AppData\Local\Programs\Python\Python310\lib\site-packages\flask\app.py", line 1473, in wsgi_app
    response = self.full_dispatch_request()
  File "c:\Users\kshotsu1.IXAS\AppData\Local\Programs\Python\Python310\lib\site-packages\flask\app.py", line 882, in full_dispatch_request
    rv = self.handle_user_exception(e)
  File "c:\Users\kshotsu1.IXAS\AppData\Local\Programs\Python\Python310\lib\site-packages\flask\app.py", line 880, in full_dispatch_request
    rv = self.dispatch_request()
  File "c:\Users\kshotsu1.IXAS\AppData\Local\Programs\Python\Python310\lib\site-packages\flask\app.py", line 865, in dispatch_request
    return self.ensure_sync(self.view_functions[rule.endpoint])(**view_args)  # type: ignore[no-any-return]
  File "C:\thread-site\vulnerability_codes\src\app.py", line 162, in my_page
    my_threads = db.execute(sql).fetchall()
sqlite3.OperationalError: no such column: ota7

[2024-12-13 11:23:12,349] ERROR: Exception on /my_page [GET]
Traceback (most recent call last):
  File "c:\Users\kshotsu1.IXAS\AppData\Local\Programs\Python\Python310\lib\site-packages\flask\app.py", line 1473, in wsgi_app
    response = self.full_dispatch_request()
  File "c:\Users\kshotsu1.IXAS\AppData\Local\Programs\Python\Python310\lib\site-packages\flask\app.py", line 882, in full_dispatch_request
    rv = self.handle_user_exception(e)
  File "c:\Users\kshotsu1.IXAS\AppData\Local\Programs\Python\Python310\lib\site-packages\flask\app.py", line 880, in full_dispatch_request
    rv = self.dispatch_request()
  File "c:\Users\kshotsu1.IXAS\AppData\Local\Programs\Python\Python310\lib\site-packages\flask\app.py", line 865, in dispatch_request
    return self.ensure_sync(self.view_functions[rule.endpoint])(**view_args)  # type: ignore[no-any-return]
  File "C:\thread-site\vulnerability_codes\src\app.py", line 162, in my_page
    my_threads = db.execute(sql).fetchall()
sqlite3.OperationalError: no such column: ota7

[2024-12-13 11:23:12,509] ERROR: Exception on /my_page [GET]
Traceback (most recent call last):
  File "c:\Users\kshotsu1.IXAS\AppData\Local\Programs\Python\Python310\lib\site-packages\flask\app.py", line 1473, in wsgi_app
    response = self.full_dispatch_request()
  File "c:\Users\kshotsu1.IXAS\AppData\Local\Programs\Python\Python310\lib\site-packages\flask\app.py", line 882, in full_dispatch_request
    rv = self.handle_user_exception(e)
  File "c:\Users\kshotsu1.IXAS\AppData\Local\Programs\Python\Python310\lib\site-packages\flask\app.py", line 880, in full_dispatch_request
    rv = self.dispatch_request()
  File "c:\Users\kshotsu1.IXAS\AppData\Local\Programs\Python\Python310\lib\site-packages\flask\app.py", line 865, in dispatch_request
    return self.ensure_sync(self.view_functions[rule.endpoint])(**view_args)  # type: ignore[no-any-return]
  File "C:\thread-site\vulnerability_codes\src\app.py", line 162, in my_page
    my_threads = db.execute(sql).fetchall()
sqlite3.OperationalError: no such column: ota7

[2024-12-13 11:23:12,660] ERROR: Exception on /my_page [GET]
Traceback (most recent call last):
  File "c:\Users\kshotsu1.IXAS\AppData\Local\Programs\Python\Python310\lib\site-packages\flask\app.py", line 1473, in wsgi_app
    response = self.full_dispatch_request()
  File "c:\Users\kshotsu1.IXAS\AppData\Local\Programs\Python\Python310\lib\site-packages\flask\app.py", line 882, in full_dispatch_request
    rv = self.handle_user_exception(e)
  File "c:\Users\kshotsu1.IXAS\AppData\Local\Programs\Python\Python310\lib\site-packages\flask\app.py", line 880, in full_dispatch_request
    rv = self.dispatch_request()
  File "c:\Users\kshotsu1.IXAS\AppData\Local\Programs\Python\Python310\lib\site-packages\flask\app.py", line 865, in dispatch_request
    return self.ensure_sync(self.view_functions[rule.endpoint])(**view_args)  # type: ignore[no-any-return]
  File "C:\thread-site\vulnerability_codes\src\app.py", line 162, in my_page
    my_threads = db.execute(sql).fetchall()
sqlite3.OperationalError: no such column: ota7

[2024-12-13 11:26:53,839] ERROR: Exception on /my_page [GET]
Traceback (most recent call last):
  File "c:\Users\kshotsu1.IXAS\AppData\Local\Programs\Python\Python310\lib\site-packages\flask\app.py", line 1473, in wsgi_app
    response = self.full_dispatch_request()
  File "c:\Users\kshotsu1.IXAS\AppData\Local\Programs\Python\Python310\lib\site-packages\flask\app.py", line 882, in full_dispatch_request
    rv = self.handle_user_exception(e)
  File "c:\Users\kshotsu1.IXAS\AppData\Local\Programs\Python\Python310\lib\site-packages\flask\app.py", line 880, in full_dispatch_request
    rv = self.dispatch_request()
  File "c:\Users\kshotsu1.IXAS\AppData\Local\Programs\Python\Python310\lib\site-packages\flask\app.py", line 865, in dispatch_request
    return self.ensure_sync(self.view_functions[rule.endpoint])(**view_args)  # type: ignore[no-any-return]
  File "C:\thread-site\vulnerability_codes\src\app.py", line 162, in my_page
    my_threads = db.execute(sql).fetchall()
sqlite3.OperationalError: no such column: ota7

[2024-12-13 11:27:17,111] ERROR: Exception on /my_page [GET]
Traceback (most recent call last):
  File "c:\Users\kshotsu1.IXAS\AppData\Local\Programs\Python\Python310\lib\site-packages\flask\app.py", line 1473, in wsgi_app
    response = self.full_dispatch_request()
  File "c:\Users\kshotsu1.IXAS\AppData\Local\Programs\Python\Python310\lib\site-packages\flask\app.py", line 882, in full_dispatch_request
    rv = self.handle_user_exception(e)
  File "c:\Users\kshotsu1.IXAS\AppData\Local\Programs\Python\Python310\lib\site-packages\flask\app.py", line 880, in full_dispatch_request
    rv = self.dispatch_request()
  File "c:\Users\kshotsu1.IXAS\AppData\Local\Programs\Python\Python310\lib\site-packages\flask\app.py", line 865, in dispatch_request
    return self.ensure_sync(self.view_functions[rule.endpoint])(**view_args)  # type: ignore[no-any-return]
  File "C:\thread-site\vulnerability_codes\src\app.py", line 162, in my_page
    my_threads = db.execute(sql).fetchall()
sqlite3.OperationalError: no such column: ota7
